<?xml version="1.0" ?>
<!-- =================================================================================== -->
<!-- |    This document was autogenerated by xacro from hcr_robot.xacro                | -->
<!-- |    EDITING THIS FILE BY HAND IS NOT RECOMMENDED                                 | -->
<!-- =================================================================================== -->
<robot name="hcr_robot">
  <material name="silver">
    <color rgba="0.700 0.700 0.700 1.000"/>
  </material>
  <material name="orange">
    <color rgba="0.8 0.2 0.1 1.0"/>
  </material>
  <material name="black">
    <color rgba="0.5 0.5 0.5 1.0"/>
  </material>
  <material name="grey">
    <color rgba="0.2 0.2 0.2 1.0"/>
  </material>
  <!--gazebo>
    <plugin filename="libgazebo_ros_control.so" name="control"/>
  </gazebo-->
  <link name="world" />
    <!-- BASE LINK -->
    <!--link name="base_link">
        <visual>
            <origin rpy="0 0 0" xyz="0 0 0.01" />
            <material name="black">
                   <color rgba="0.0 0.0 0.0 1.0"/>
            </material>
             
        </visual>
        <collision>
            <origin rpy="0 0 0" xyz="0 0 0.01" />
            <geometry>
                <cylinder length="0.02" radius="0.5" />
            </geometry>
        </collision>
        
        <inertial>

            <mass value="0.1" />
            <inertia ixx="0.03" iyy="0.03" izz="0.03" ixy="0.0" ixz="0.0" iyz="0.0" />
        </inertial>

    </link-->
  <gazebo reference="base_link">
    <material>Gazebo/Black</material>
    <mu1>0.2</mu1>
    <mu2>0.2</mu2>
    <selfCollide>true</selfCollide>
    <gravity>true</gravity>
  </gazebo>
  <gazebo reference="link1_1">
    <material>Gazebo/Black</material>
    <mu1>0.2</mu1>
    <mu2>0.2</mu2>
    <selfCollide>true</selfCollide>
  </gazebo>
  <gazebo reference="link2_1">
    <material>Gazebo/Black</material>
    <mu1>0.2</mu1>
    <mu2>0.2</mu2>
    <selfCollide>true</selfCollide>
  </gazebo>
  <gazebo reference="link3_1">
    <material>Gazebo/Orange</material>
    <mu1>0.2</mu1>
    <mu2>0.2</mu2>
    <selfCollide>true</selfCollide>
  </gazebo>
  <gazebo reference="link4_1">
    <material>Gazebo/Orange</material>
    <mu1>0.2</mu1>
    <mu2>0.2</mu2>
    <selfCollide>true</selfCollide>
  </gazebo>
  <gazebo reference="link5_1">
    <material>Gazebo/Orange</material>
    <mu1>0.2</mu1>
    <mu2>0.2</mu2>
    <selfCollide>true</selfCollide>
  </gazebo>
  <gazebo reference="link6_1">
    <material>Gazebo/Grey</material>
    <mu1>0.2</mu1>
    <mu2>0.2</mu2>
    <selfCollide>true</selfCollide>
  </gazebo>
  <!-- LINK 1 -->
  <link name="base_link">
    <inertial>
      <origin rpy="0 0 0" xyz="0.044693591972953806 -9.689819846991377e-05 0.013982771179495564"/>
      <mass value="4.071462983655495"/>
      <inertia ixx="0.004614" ixy="-2e-05" ixz="-0.000189" iyy="0.063084" iyz="0.0" izz="0.067151"/>
    </inertial>
    <visual>
      <origin rpy="0 0 0" xyz="0 0 0"/>
      <geometry>
        <mesh filename="package://hcr_robot_description/meshes/base_link.stl" scale="0.001 0.001 0.001"/>
      </geometry>
      <material name="black"/>
    </visual>
    <collision>
      <origin rpy="0 0 0" xyz="0 0 0"/>
      <geometry>
        <mesh filename="package://hcr_robot_description/meshes/base_link.stl" scale="0.001 0.001 0.001"/>
      </geometry>
    </collision>
  </link>
  <!-- joint -->
  <joint name="fixed" type="fixed">
        <parent link="world" />
        <child link="base_link" />
  </joint>
  <link name="link1_1">
    <inertial>
      <origin rpy="0 0 0" xyz="-0.009232924655966162 5.611908895686318e-08 0.08981078121700108"/>
      <mass value="17.125748524580114"/>
      <inertia ixx="0.054601" ixy="0.0" ixz="0.004569" iyy="0.061186" iyz="-0.0" izz="0.036738"/>
    </inertial>
    <visual>
      <origin rpy="0 0 0" xyz="-0.0 0.0 -0.03"/>
      <geometry>
        <mesh filename="package://hcr_robot_description/meshes/link1_1.stl" scale="0.001 0.001 0.001"/>
      </geometry>
      <material name="black"/>
    </visual>
    <collision>
      <origin rpy="0 0 0" xyz="-0.0 0.0 -0.03"/>
      <geometry>
        <mesh filename="package://hcr_robot_description/meshes/link1_1.stl" scale="0.001 0.001 0.001"/>
      </geometry>
    </collision>
  </link>
  <link name="link2_1">
    <inertial>
      <origin rpy="0 0 0" xyz="-0.08134423156498356 0.0004999972193747809 0.21200027982915884"/>
      <mass value="32.073698785630135"/>
      <inertia ixx="1.334728" ixy="-5e-06" ixz="-0.002068" iyy="1.368804" iyz="-0.003172" izz="0.0845"/>
    </inertial>
    <visual>
      <origin rpy="0 0 0" xyz="0.0785 0.0 -0.148778"/>
      <geometry>
        <mesh filename="package://hcr_robot_description/meshes/link2_1.stl" scale="0.001 0.001 0.001"/>
      </geometry>
      <material name="black"/>
    </visual>
    <collision>
      <origin rpy="0 0 0" xyz="0.0785 0.0 -0.148778"/>
      <geometry>
        <mesh filename="package://hcr_robot_description/meshes/link2_1.stl" scale="0.001 0.001 0.001"/>
      </geometry>
    </collision>
  </link>
  <link name="link3_1">
    <inertial>
      <origin rpy="0 0 0" xyz="0.03733088153046067 -8.45436915776097e-06 0.32700293666580915"/>
      <mass value="6.636542484506931"/>
      <inertia ixx="0.008668" ixy="-0.0" ixz="0.001661" iyy="0.014027" iyz="0.0" izz="0.010649"/>
    </inertial>
    <visual>
      <origin rpy="0 0 0" xyz="0.077848 -0.001 -0.572778"/>
      <geometry>
        <mesh filename="package://hcr_robot_description/meshes/link3_1.stl" scale="0.001 0.001 0.001"/>
      </geometry>
      <material name="orange"/>
    </visual>
    <collision>
      <origin rpy="0 0 0" xyz="0.077848 -0.001 -0.572778"/>
      <geometry>
        <mesh filename="package://hcr_robot_description/meshes/link3_1.stl" scale="0.001 0.001 0.001"/>
      </geometry>
    </collision>
  </link>
  <link name="link4_1">
    <inertial>
      <origin rpy="0 0 0" xyz="-0.053462210233883714 -3.2261679182082545e-07 0.022076827880824546"/>
      <mass value="6.518501202798632"/>
      <inertia ixx="0.011005" ixy="-0.0" ixz="0.001222" iyy="0.012783" iyz="0.0" izz="0.007491"/>
    </inertial>
    <visual>
      <origin rpy="0 0 0" xyz="0.107864 -0.000992 -0.911345"/>
      <geometry>
        <mesh filename="package://hcr_robot_description/meshes/link4_1.stl" scale="0.001 0.001 0.001"/>
      </geometry>
      <material name="orange"/>
    </visual>
    <collision>
      <origin rpy="0 0 0" xyz="0.107864 -0.000992 -0.911345"/>
      <geometry>
        <mesh filename="package://hcr_robot_description/meshes/link4_1.stl" scale="0.001 0.001 0.001"/>
      </geometry>
    </collision>
  </link>
  <link name="link5_1">
    <inertial>
      <origin rpy="0 0 0" xyz="-0.022082116809040042 -5.860596366637823e-07 0.0534553107989999"/>
      <mass value="6.518501237017786"/>
      <inertia ixx="0.007541" ixy="0.0" ixz="0.001224" iyy="0.012794" iyz="-0.0" izz="0.010966"/>
    </inertial>
    <visual>
      <origin rpy="0 0 0" xyz="0.169864 -0.000992 -1.000941"/>
      <geometry>
        <mesh filename="package://hcr_robot_description/meshes/link5_1.stl" scale="0.001 0.001 0.001"/>
      </geometry>
      <material name="orange"/>
    </visual>
    <collision>
      <origin rpy="0 0 0" xyz="0.169864 -0.000992 -1.000941"/>
      <geometry>
        <mesh filename="package://hcr_robot_description/meshes/link5_1.stl" scale="0.001 0.001 0.001"/>
      </geometry>
    </collision>
  </link>
  <link name="link6_1">
    <inertial>
      <origin rpy="0 0 0" xyz="-0.019264152679962065 -4.5474100852818493e-07 -0.0005907014657897669"/>
      <mass value="1.6914762668461325"/>
      <inertia ixx="0.001473" ixy="0.0" ixz="-8e-06" iyy="0.00094" iyz="0.0" izz="0.000976"/>
    </inertial>
    <visual>
      <origin rpy="0 0 0" xyz="0.25946 -0.000992 -1.062941"/>
      <geometry>
        <mesh filename="package://hcr_robot_description/meshes/link6_1.stl" scale="0.001 0.001 0.001"/>
      </geometry>
      <material name="grey"/>
    </visual>
    <collision>
      <origin rpy="0 0 0" xyz="0.25946 -0.000992 -1.062941"/>
      <geometry>
        <mesh filename="package://hcr_robot_description/meshes/link6_1.stl" scale="0.001 0.001 0.001"/>
      </geometry>
    </collision>
  </link>
  <joint name="joint_1" type="revolute">
    <origin rpy="0 0 0" xyz="0.0 0.0 0.03"/>
    <parent link="base_link"/>
    <child link="link1_1"/>
    <axis xyz="0.0 -0.0 1.0"/>
    <limit effort="100" lower="0.0" upper="6.283185" velocity="100"/>
  </joint>
  <joint name="joint_2" type="revolute">
    <origin rpy="0 0 0" xyz="-0.0785 0.0 0.118778"/>
    <parent link="link1_1"/>
    <child link="link2_1"/>
    <axis xyz="-1.0 0.0 0.0"/>
    <limit effort="100" lower="-1.570796" upper="1.570796" velocity="100"/>
  </joint>
  <joint name="joint_3" type="revolute">
    <origin rpy="0 0 0" xyz="0.000652 0.001 0.424"/>
    <parent link="link2_1"/>
    <child link="link3_1"/>
    <axis xyz="1.0 0.0 0.0"/>
    <limit effort="100" lower="-2.268928" upper="2.268928" velocity="100"/>
  </joint>
  <joint name="joint_4" type="revolute">
    <origin rpy="0 0 0" xyz="-0.030016 -8e-06 0.338567"/>
    <parent link="link3_1"/>
    <child link="link4_1"/>
    <axis xyz="-1.0 0.0 -0.0"/>
    <limit effort="100" lower="-2.96706" upper="2.96706" velocity="100"/>
  </joint>
  <joint name="joint_5" type="revolute">
    <origin rpy="0 0 0" xyz="-0.062 0.0 0.089596"/>
    <parent link="link4_1"/>
    <child link="link5_1"/>
    <axis xyz="-0.0 -0.0 1.0"/>
    <limit effort="100" lower="-2.094395" upper="2.094395" velocity="100"/>
  </joint>
  <joint name="joint_6" type="revolute">
    <origin rpy="0 0 0" xyz="-0.089596 0.0 0.062"/>
    <parent link="link5_1"/>
    <child link="link6_1"/>
    <axis xyz="-1.0 -0.0 0.0"/>
    <limit effort="100" lower="0.0" upper="6.283185" velocity="100"/>
  </joint>
  <transmission name="trans_joint_1">
        <type>transmission_interface/SimpleTransmission</type>
        <joint name="joint_1">
            <hardwareInterface>hardware_interface/PositionJointInterface</hardwareInterface>
        </joint>
        <actuator name="joint_1_motor">
            <hardwareInterface>hardware_interface/PositionJointInterface</hardwareInterface>
            <mechanicalReduction>1</mechanicalReduction>
        </actuator>
    </transmission>
    <transmission name="trans_joint_2">
        <type>transmission_interface/SimpleTransmission</type>
        <joint name="joint_2">
            <hardwareInterface>hardware_interface/PositionJointInterface</hardwareInterface>
        </joint>
        <actuator name="joint_2_motor">
            <hardwareInterface>hardware_interface/PositionJointInterface</hardwareInterface>
            <mechanicalReduction>1</mechanicalReduction>
        </actuator>
    </transmission>
    <transmission name="trans_joint_3">
        <type>transmission_interface/SimpleTransmission</type>
        <joint name="joint_3">
            <hardwareInterface>hardware_interface/PositionJointInterface</hardwareInterface>
        </joint>
        <actuator name="joint_3_motor">
            <hardwareInterface>hardware_interface/PositionJointInterface</hardwareInterface>
            <mechanicalReduction>1</mechanicalReduction>
        </actuator>
    </transmission>
    <transmission name="trans_joint_4">
        <type>transmission_interface/SimpleTransmission</type>
        <joint name="joint_4">
            <hardwareInterface>hardware_interface/PositionJointInterface</hardwareInterface>
        </joint>
        <actuator name="joint_4_motor">
            <hardwareInterface>hardware_interface/PositionJointInterface</hardwareInterface>
            <mechanicalReduction>1</mechanicalReduction>
        </actuator>
    </transmission>
    <transmission name="trans_joint_5">
        <type>transmission_interface/SimpleTransmission</type>
        <joint name="joint_5">
            <hardwareInterface>hardware_interface/PositionJointInterface</hardwareInterface>
        </joint>
        <actuator name="joint_5_motor">
            <hardwareInterface>hardware_interface/PositionJointInterface</hardwareInterface>
            <mechanicalReduction>1</mechanicalReduction>
        </actuator>
    </transmission>
    <transmission name="trans_joint_6">
        <type>transmission_interface/SimpleTransmission</type>
        <joint name="joint_6">
            <hardwareInterface>hardware_interface/PositionJointInterface</hardwareInterface>
        </joint>
        <actuator name="joint_6_motor">
            <hardwareInterface>hardware_interface/PositionJointInterface</hardwareInterface>
            <mechanicalReduction>1</mechanicalReduction>
        </actuator>
    </transmission>
    <gazebo>
        <plugin name="gazebo_ros_control" filename="libgazebo_ros_control.so">
            <robotNamespace>/</robotNamespace>
        </plugin>
    </gazebo>
</robot>

